<?xml version="1.0" encoding="utf-8"?>
<!-- This URDF was automatically created by SolidWorks to URDF Exporter! Originally created by Stephen Brawner (brawner@gmail.com) 
     Commit Version: 1.6.0-4-g7f85cfe  Build Version: 1.6.7995.38578
     For more information, please see http://wiki.ros.org/sw_urdf_exporter -->
<robot
  name="skyline_urdf" 
  xmlns:xacro="http://ros.org/wiki/xacro">

  <link name="world"/>
  
  <joint name="base_joint" type="fixed">
    <parent link="world"/>
    <child link="base_link"/>
    <origin rpy="0 0 0" xyz="0.0 0.0 0.0"/>
    </joint>


  <link
    name="base_link">
    <inertial>
      <origin
        xyz="3.9767E-05 0.0075231 -2.3978E-05"
        rpy="0 0 0" />
      <mass
        value="5.6578" />
      <inertia
        ixx="0.14702"
        ixy="-4.4448E-08"
        ixz="-4.8616E-08"
        iyy="0.73311"
        iyz="-1.0263E-09"
        izz="0.58618" />
    </inertial>
    <visual>
      <origin
        xyz="0 0 0"
        rpy="0 0 0" />
      <geometry>
        <mesh
          filename="package://skyline_urdf/meshes/base_link.STL" />
      </geometry>
      <material
        name="">
        <color
          rgba="0.75294 0.75294 0.75294 1" />
      </material>
    </visual>
    <collision>
      <origin
        xyz="0 0 0"
        rpy="0 0 0" />
      <geometry>
        <mesh
          filename="package://skyline_urdf/meshes/base_link.STL" />
      </geometry>
    </collision>
  </link>


  <link
    name="link_1">
    <inertial>
      <origin
        xyz="0.0028663 -0.015314 -0.0013736"
        rpy="0 0 0" />
      <mass
        value="0.32273" />
      <inertia
        ixx="0.00029459"
        ixy="1.3858E-05"
        ixz="2.0977E-06"
        iyy="0.000642"
        iyz="-2.7664E-06"
        izz="0.00040997" />
    </inertial>
    <visual>
      <origin
        xyz="0 0 0"
        rpy="0 0 0" />
      <geometry>
        <mesh
          filename="package://skyline_urdf/meshes/link_1.STL" />
      </geometry>
      <material
        name="">
        <color
          rgba="0.79216 0.81961 0.93333 1" />
      </material>
    </visual>
    <collision>
      <origin
        xyz="0 0 0"
        rpy="0 0 0" />
      <geometry>
        <mesh
          filename="package://skyline_urdf/meshes/link_1.STL" />
      </geometry>
    </collision>
  </link>
  <joint
    name="joint_0"
    type="revolute">
    <origin
      xyz="0.0005 0.0001 0.071125"
      rpy="-1.5708 0 3.1416" />
    <parent
      link="base_link" />
    <child
      link="link_1" />
    <axis
      xyz="0 1 0" />
    <limit
      lower="0"
      upper="${2*pi}"
      effort="300"
      velocity="3" />
  </joint>


  <link
    name="link_2">
    <inertial>
      <origin
        xyz="0.00026152 0.027731 -0.13538"
        rpy="0 0 0" />
      <mass
        value="0.47089" />
      <inertia
        ixx="0.00036399"
        ixy="-1.4586E-06"
        ixz="-1.0366E-06"
        iyy="0.00037487"
        iyz="1.9539E-06"
        izz="0.00015851" />
    </inertial>
    <visual>
      <origin
        xyz="0 0 0"
        rpy="0 0 0" />
      <geometry>
        <mesh
          filename="package://skyline_urdf/meshes/link_2.STL" />
      </geometry>
      <material
        name="">
        <color
          rgba="0.79216 0.81961 0.93333 1" />
      </material>
    </visual>
    <collision>
      <origin
        xyz="0 0 0"
        rpy="0 0 0" />
      <geometry>
        <mesh
          filename="package://skyline_urdf/meshes/link_2.STL" />
      </geometry>
    </collision>
  </link>
  <joint
    name="joint_1"
    type="revolute">
    <origin
      xyz="0 -0.044775 0.027271"
      rpy="-1.5708 0 0" />
    <parent
      link="link_1" />
    <child
      link="link_2" />
    <axis
      xyz="0 0 1" />
    <limit
      lower="0"
      upper="${pi}"
      effort="300"
      velocity="3" />
  </joint>


  <link
    name="link_3">
    <inertial>
      <origin
        xyz="-9.1345E-08 0.027755 -0.1351"
        rpy="0 0 0" />
      <mass
        value="0.46993" />
      <inertia
        ixx="0.00036418"
        ixy="5.5357E-10"
        ixz="6.5718E-10"
        iyy="0.00037396"
        iyz="1.473E-06"
        izz="0.00015835" />
    </inertial>
    <visual>
      <origin
        xyz="0 0 0"
        rpy="0 0 0" />
      <geometry>
        <mesh
          filename="package://skyline_urdf/meshes/link_3.STL" />
      </geometry>
      <material
        name="">
        <color
          rgba="0.79216 0.81961 0.93333 1" />
      </material>
    </visual>
    <collision>
      <origin
        xyz="0 0 0"
        rpy="0 0 0" />
      <geometry>
        <mesh
          filename="package://skyline_urdf/meshes/link_3.STL" />
      </geometry>
    </collision>
  </link>
  <joint
    name="joint_2"
    type="revolute">
    <origin
      xyz="0 0.001893 -0.28455"
      rpy="0 0 0" />
    <parent
      link="link_2" />
    <child
      link="link_3" />
    <axis
      xyz="0 0 1" />
    <limit
      lower="0"
      upper="${pi/2}"
      effort="300"
      velocity="3" />
  </joint>


  <link
    name="link_4">
    <inertial>
      <origin
        xyz="-0.02091 0.026578 0.04288"
        rpy="0 0 0" />
      <mass
        value="0.13387" />
      <inertia
        ixx="7.5889E-05"
        ixy="5.7749E-07"
        ixz="1.4261E-05"
        iyy="8.4688E-05"
        iyz="-1.7745E-06"
        izz="9.7666E-05" />
    </inertial>
    <visual>
      <origin
        xyz="0 0 0"
        rpy="0 0 0" />
      <geometry>
        <mesh
          filename="package://skyline_urdf/meshes/link_4.STL" />
      </geometry>
      <material
        name="">
        <color
          rgba="0.79216 0.81961 0.93333 1" />
      </material>
    </visual>
    <collision>
      <origin
        xyz="0 0 0"
        rpy="0 0 0" />
      <geometry>
        <mesh
          filename="package://skyline_urdf/meshes/link_4.STL" />
      </geometry>
    </collision>
  </link>
  <joint
    name="joint_3"
    type="revolute">
    <origin
      xyz="0 0.001893 -0.28455"
      rpy="3.1416 -0.0067822 3.1416" />
    <parent
      link="link_3" />
    <child
      link="link_4" />
    <axis
      xyz="0 0 1" />
    <limit
      lower="${-1*pi/4}"
      upper="${pi/4}"
      effort="300"
      velocity="3" />
  </joint>


  <link
    name="end_effector_link">
    <inertial>
      <origin
        xyz="7.096E-05 -0.020217 0.00033158"
        rpy="0 0 0" />
      <mass
        value="0.21271" />
      <inertia
        ixx="0.00032373"
        ixy="3.8989E-06"
        ixz="-4.7319E-07"
        iyy="0.00025001"
        iyz="6.6279E-07"
        izz="9.7621E-05" />
    </inertial>
    <visual>
      <origin
        xyz="0 0 0"
        rpy="0 0 0" />
      <geometry>
        <mesh
          filename="package://skyline_urdf/meshes/end_effector_link.STL" />
      </geometry>
      <material
        name="">
        <color
          rgba="0.79216 0.81961 0.93333 1" />
      </material>
    </visual>
    <collision>
      <origin
        xyz="0 0 0"
        rpy="0 0 0" />
      <geometry>
        <mesh
          filename="package://skyline_urdf/meshes/end_effector_link.STL" />
      </geometry>
    </collision>
  </link>
  <joint
    name="joint_4"
    type="revolute">
    <origin
      xyz="0.0032807 0.026793 0.10607"
      rpy="-1.5708 0.0067822 3.1416" />
    <parent
      link="link_4" />
    <child
      link="end_effector_link" />
    <axis
      xyz="0 1 0" />
    <limit
      lower="${-1*pi/4}"
      upper="${pi/4}"
      effort="300"
      velocity="3" />
  </joint>




  <!-- Transmission -->
  <transmission name="link_1_trans">
    <type>transmission_interface/SimpleTransmission</type>
    <joint name="joint_0">
      <hardwareInterface>hardware_interface/PositionJointInterface</hardwareInterface>
    </joint>
    <actuator name="link_1_motor">
      <hardwareInterface>hardware_interface/PositionJointInterface</hardwareInterface>
      <mechanicalReduction>1</mechanicalReduction>
    </actuator>
  </transmission>

  <transmission name="link_2_trans">
    <type>transmission_interface/SimpleTransmission</type>
    <joint name="joint_1">
      <hardwareInterface>hardware_interface/PositionJointInterface</hardwareInterface>
    </joint>
    <actuator name="link_2_motor">
      <hardwareInterface>hardware_interface/PositionJointInterface</hardwareInterface>
      <mechanicalReduction>1</mechanicalReduction>
    </actuator>
  </transmission>

  <transmission name="link_3_trans">
    <type>transmission_interface/SimpleTransmission</type>
    <joint name="joint_2">
      <hardwareInterface>hardware_interface/PositionJointInterface</hardwareInterface>
    </joint>
    <actuator name="link_3_motor">
      <hardwareInterface>hardware_interface/PositionJointInterface</hardwareInterface>
      <mechanicalReduction>1</mechanicalReduction>
    </actuator>
  </transmission>

  <transmission name="link_4_trans">
    <type>transmission_interface/SimpleTransmission</type>
    <joint name="joint_3">
      <hardwareInterface>hardware_interface/PositionJointInterface</hardwareInterface>
    </joint>
    <actuator name="link_4_motor">
      <hardwareInterface>hardware_interface/PositionJointInterface</hardwareInterface>
      <mechanicalReduction>1</mechanicalReduction>
    </actuator>
  </transmission>



  <transmission name="end_effector_link_trans">
    <type>transmission_interface/SimpleTransmission</type>
    <joint name="joint_4">
      <hardwareInterface>hardware_interface/PositionJointInterface</hardwareInterface>
    </joint>
    <actuator name="end_effector_link_motor">
      <hardwareInterface>hardware_interface/PositionJointInterface</hardwareInterface>
      <mechanicalReduction>1</mechanicalReduction>
    </actuator>
  </transmission>

  <gazebo>
    <plugin name="gazebo_ros_control" filename="libgazebo_ros_control.so">
    <robotNamespace>/Skyline</robotNamespace>
    </plugin>
  </gazebo>

  <gazebo reference="link_1">
    <selfCollide>true</selfCollide>
  </gazebo>

  <gazebo reference="link_2">
    <selfCollide>true</selfCollide>
  </gazebo>

  <gazebo reference="link_3">
    <selfCollide>true</selfCollide>
  </gazebo>

  <gazebo reference="link_4">
    <selfCollide>true</selfCollide>
  </gazebo>

  <gazebo reference="end_effector_link">
    <selfCollide>true</selfCollide>
  </gazebo>


</robot>